

## 错误处理

Rust 有一套独特的处理异常情况的机制，它并不像其它语言中的 try 机制那样简单。

首先，程序中一般会出现两种错误：可恢复错误和不可恢复错误。

可恢复错误的典型案例是文件访问错误，如果访问一个文件失败，有可能是因为它正在被占用，是正常的，我们可以通过等待来解决。

但还有一种错误是由编程中无法解决的逻辑错误导致的，例如访问数组末尾以外的位置。

大多数编程语言不区分这两种错误，并用 Exception （异常）类来表示错误。在 Rust 中没有 Exception。

对于可恢复错误用 `Result<T, E>` 类来处理，对于不可恢复错误使用 `panic!` 宏来处理。


#### 不可恢复错误

```rust
fn main() {
    panic!("error occured");
    println!("Hello, Rust");
}
```

提示使用 `RUST_BACKTRACE=1` 来回溯, 因此执行 `RUST_BACKTRACE=1 cargo run` 来获取错误位置

#### 可恢复错误

在 Rust 中通过 `Result<T, E>` 枚举类作返回值来进行异常表达

```rust
enum Result<T, E> {
    Ok(T),
    Err(E),
}
```

```rust
use std::fs::File;

fn main() {
    let f = File::open("hello.txt");
    if let Ok(_) = f {
        println!("File opened successfully.");
    }

    // 如果想使一个可恢复错误按不可恢复错误处理
    // Result 类提供了两个办法：unwrap() 和 expect(message: &str)
    let f1 = File::open("hello.txt").unwrap();
    let f2 = File::open("hello.txt").expect("Failed to open.");
}
```

## 可恢复错误的传递

```rust
fn func(i: i32) -> Result<i32, String> {
    if i <= 0 {
        // 返回错误并描述错误原因
        return Err("Number not biger than zero".to_string());
    }

    // 返回正确, 并返回一个值
    Ok(i + 1)
}

fn gunc(i: i32) -> Result<i32, String> {
    // ? 将 Result 类非异常的值直接取出, 如果有错误则直接抛出并返回
    let t = func(i)?;
    Ok(t)
}


let ret = gunc(1);

match ret {
    Ok(value) => println!("ok, {value}"),
    Err(emsg) => println!("{emsg}"),
}
```